Workbook

Sheet Itens
A1: COD_ID | B1: Descrição | C1: Unidade | D1: Familia | E1: Preço_Médio (R$)
A2: CAN-HER-001 | B2: Glifosato 480 SL | C2: L | D2: Herbicida | E2: 22
A3: CAN-HER-002 | B3: 2,4-D (sal amina) | C3: L | D3: Herbicida | E3: 18
A4: CAN-HER-003 | B4: Atrazina 500 SC | C4: L | D4: Herbicida | E4: 24
A5: CAN-HER-004 | B5: Hexazinona 250 SC | C5: L | D5: Herbicida | E5: 110
A6: CAN-HER-005 | B6: Diuron 500 SC | C6: L | D6: Herbicida | E6: 30
A7: CAN-HER-006 | B7: Tebutiuron 500 WG | C7: kg | D7: Herbicida | E7: 75
A8: CAN-HER-007 | B8: Imazapic 700 WG | C8: kg | D8: Herbicida | E8: 320
A9: CAN-HER-008 | B9: Amicarbazona 700 WG | C9: kg | D9: Herbicida | E9: 280
A10: CAN-HER-009 | B10: Metolacloro 960 EC | C10: L | D10: Herbicida | E10: 55
A11: CAN-HER-010 | B11: MSMA (concentrado solúvel) | C11: L | D11: Herbicida | E11: 45
A12: CAN-INS-001 | B12: Inseticida – Imidacloprido 200 SL | C12: L | D12: Inseticida | E12: 120
A13: CAN-INS-002 | B13: Tiametoxam 250 WG | C13: kg | D13: Inseticida | E13: 400
... A51: CAN-ADJ-002 | B51: Espalhante adesivo não iônico | C51: L | D51: Adjuvante | E51: 35

Sheet Entradas
A1: Data | B1: Documento | C1: Fornecedor | D1: COD_ID | E1: Descrição | F1: Familia | G1: Unidade | H1: Quantidade | I1: Preço Unitário (R$) | J1: Valor Total (R$) | K1: Observações
A2: 45476 | B2: NF-2024-0037 | C2: AgroVale Distribuidora | D2: CAN-MIC-003 | E2: =IFERROR(VLOOKUP(D2,Itens!$A$2:$E$51,2,FALSE),"") -> Manganês (Mn) | F2: =IFERROR(VLOOKUP(D2,Itens!$A$2:$E$51,4,FALSE),"") -> Micronutriente | G2: =IFERROR(VLOOKUP(D2,Itens!$A$2:$E$51,3,FALSE),"") -> kg | H2: 100 | I2: 10.87 | J2: =IF(OR(H2="",I2=""),"",H2*I2) -> 1087 | K2: Ajuste de estoque
A3: 45480 | B3: NF-2024-0005 | C3: AgroVale Distribuidora | D3: CAN-HER-005 | E3: =IFERROR(VLOOKUP(D3,Itens!$A$2:$E$51,2,FALSE),"") -> Diuron 500 SC | F3: =IFERROR(VLOOKUP(D3,Itens!$A$2:$E$51,4,FALSE),"") -> Herbicida | G3: =IFERROR(VLOOKUP(D3,Itens!$A$2:$E$51,3,FALSE),"") -> L | H3: 250 | I3: 29.44 | J3: =IF(OR(H3="",I3=""),"",H3*I3) -> 7360 | K3: Reposição
A4: 45481 | B4: NF-2024-0028 | C4: FertiMinas | D4: CAN-FER-012 | E4: =IFERROR(VLOOKUP(D4,Itens!$A$2:$E$51,2,FALSE),"") -> NPK 08-28-16 | F4: =IFERROR(VLOOKUP(D4,Itens!$A$2:$E$51,4,FALSE),"") -> Fertilizante (NPK) | G4: =IFERROR(VLOOKUP(D4,Itens!$A$2:$E$51,3,FALSE),"") -> kg | H4: 1000 | I4: 4.04 | J4: =IF(OR(H4="",I4=""),"",H4*I4) -> 4040 | K4: Compra programada
A5: 45483 | B5: NF-2024-0045 | C5: Nutriplan | D5: CAN-ORG-002 | E5: =IFERROR(VLOOKUP(D5,Itens!$A$2:$E$51,2,FALSE),"") -> Fertilizante organomineral NPK (formulação padrão) | F5: =IFERROR(VLOOKUP(D5,Itens!$A$2:$E$51,4,FALSE),"") -> Organomineral | G5: =IFERROR(VLOOKUP(D5,Itens!$A$2:$E$51,3,FALSE),"") -> kg | H5: 2000 | I5: 2.61 | J5: =IF(OR(H5="",I5=""),"",H5*I5) -> 5220 | K5: Reposição
A6: 45499 | B6: NF-2024-0001 | C6: Planta Forte Agro | D6: CAN-HER-001 | E6: =IFERROR(VLOOKUP(D6,Itens!$A$2:$E$51,2,FALSE),"") -> Glifosato 480 SL | F6: =IFERROR(VLOOKUP(D6,Itens!$A$2:$E$51,4,FALSE),"") -> Herbicida | G6: =IFERROR(VLOOKUP(D6,Itens!$A$2:$E$51,3,FALSE),"") -> L | H6: 150 | I6: 21.21 | J6: =IF(OR(H6="",I6=""),"",H6*I6) -> 3181.5 | K6: Reposição
A7: 45529 | B7: NF-2024-0032 | C7: CoopCana | D7: CAN-CAL-003 | E7: =IFERROR(VLOOKUP(D7,Itens!$A$2:$E$51,2,FALSE),"") -> Gesso agrícola (sulfato de cálcio) | F7: =IFERROR(VLOOKUP(D7,Itens!$A$2:$E$51,4,FALSE),"") -> Condicionador de solo | G7: =IFERROR(VLOOKUP(D7,Itens!$A$2:$E$51,3,FALSE),"") -> t | H7: 50 | I7: 195.49 | J7: =IF(OR(H7="",I7=""),"",H7*I7) -> 9774.5
A8: 45531 | B8: NF-2024-0013 | C8: AgroVale Distribuidora | D8: CAN-INS-004 | E8: =IFERROR(VLOOKUP(D8,Itens!$A$2:$E$51,2,FALSE),"") -> Lambda-cialotrina 50 EC | F8: =IFERROR(VLOOKUP(D8,Itens!$A$2:$E$51,4,FALSE),"") -> Inseticida | G8: =IFERROR(VLOOKUP(D8,Itens!$A$2:$E$51,3,FALSE),"") -> L | H8: 50 | I8: 95.84 | J8: =IF(OR(H8="",I8=""),"",H8*I8) -> 4792 | K8: Ajuste de estoque
A9: 45544 | B9: NF-2024-0041 | C9: BioAgro Insumos | D9: CAN-INO-002 | E9: =IFERROR(VLOOKUP(D9,Itens!$A$2:$E$51,2,FALSE),"") -> Bacillus spp. promotor de crescimento | F9: =IFERROR(VLOOKUP(D9,Itens!$A$2:$E$51,4,FALSE),"") -> Inoculante | G9: =IFERROR(VLOOKUP(D9,Itens!$A$2:$E$51,3,FALSE),"") -> kg | H9: 60 | I9: 129.02 | J9: =IF(OR(H9="",I9=""),"",H9*I9) -> 7741.2 | K9: Ajuste de estoque
A10: 45547 | B10: NF-2024-0011 | C10: Planta Forte Agro | D10: CAN-INS-002 | E10: =IFERROR(VLOOKUP(D10,Itens!$A$2:$E$51,2,FALSE),"") -> Tiametoxam 250 WG | F10: =IFERROR(VLOOKUP(D10,Itens!$A$2:$E$51,4,FALSE),"") -> Inseticida | G10: =IFERROR(VLOOKUP(D10,Itens!$A$2:$E$51,3,FALSE),"") -> kg | H10: 15 | I10: 406.46 | J10: =IF(OR(H10="",I10=""),"",H10*I10) -> 6096.9 | K10: Reposição
A11: 45585 | B11: NF-2024-0033 | C11: Calcários Serra Azul | D11: CAN-CAL-004 | E11: =IFERROR(VLOOKUP(D11,Itens!$A$2:$E$51,2,FALSE),"") -> Cal virgem agrícola | F11: =IFERROR(VLOOKUP(D11,Itens!$A$2:$E$51,4,FALSE),"") -> Corretivo (Calagem) | G11: =IFERROR(VLOOKUP(D11,Itens!$A$2:$E$51,3,FALSE),"") -> kg | H11: 1000 | I11: 1.15 | J11: =IF(OR(H11="",I11=""),"",H11*I11) -> 1150 | K11: Ajuste de estoque
A12: 45605 | B12: NF-2024-0025 | C12: CoopCana | D12: CAN-FER-009 | E12: =IFERROR(VLOOKUP(D12,Itens!$A$2:$E$51,2,FALSE),"") -> Superfosfato triplo (TSP) | F12: =IFERROR(VLOOKUP(D12,Itens!$A$2:$E$51,4,FALSE),"") -> Fosfatado | G12: =IFERROR(VLOOKUP(D12,Itens!$A$2:$E$51,3,FALSE),"") -> kg | H12: 20000 | I12: 3.49 | J12: =IF(OR(H12="",I12=""),"",H12*I12) -> 69800 | K12: Reposição
A13: 45608 | B13: NF-2024-0044 | C13: CoopCana | D13: CAN-ORG-002 | E13: =IFERROR(VLOOKUP(D13,Itens!$A$2:$E$51,2,FALSE),"") -> Fertilizante organomineral NPK (formulação padrão) | F13: =IFERROR(VLOOKUP(D13,Itens!$A$2:$E$51,4,FALSE),"") -> Organomineral | G13: =IFERROR(VLOOKUP(D13,Itens!$A$2:$E$51,3,FALSE),"") -> kg | H13: 8000 | I13: 2.81 | J13: =IF(OR(H13="",I13=""),"",H13*I13) -> 22480 | K13: Compra programada
A14: 45609 | B14: NF-2024-0046 | C14: CoopCana | D14: CAN-ADJ-001 | E14: =IFERROR(VLOOKUP(D14,Itens!$A$2:$E$51,2,FALSE),"") -> Óleo mineral emulsionável | F14: =IFERROR(VLOOKUP(D14,Itens!$A$2:$E$51,4,FALSE),"") -> Adjuvante | G14: =IFERROR(VLOOKUP(D14,Itens!$A$2:$E$51,3,FALSE),"") -> L | H14: 80 | I14: 21.57 | J14: =IF(OR(H14="",I14=""),"",H14*I14) -> 1725.6 | K14: Safra/Tratos
A15: 45615 | B15: NF-2024-0017 | C15: Planta Forte Agro | D15: CAN-NEM-002 | E15: =IFERROR(VLOOKUP(D15,Itens!$A$2:$E$51,2,FALSE),"") -> Abamectina 18 EC | F15: =IFERROR(VLOOKUP(D15,Itens!$A$2:$E$51,4,FALSE),"") -> Nematicida | G15: =IFERROR(VLOOKUP(D15,Itens!$A$2:$E$51,3,FALSE),"") -> L | H15: 300 | I15: 206 | J15: =IF(OR(H15="",I15=""),"",H15*I15) -> 61800 | K15: Compra programada
A16: 45630 | B16: NF-2024-0018 | C16: Planta Forte Agro | D16: CAN-NEM-003 | E16: =IFERROR(VLOOKUP(D16,Itens!$A$2:$E$51,2,FALSE),"") -> Bacillus firmus | F16: =IFERROR(VLOOKUP(D16,Itens!$A$2:$E$51,4,FALSE),"") -> Nematicida | G16: =IFERROR(VLOOKUP(D16,Itens!$A$2:$E$51,3,FALSE),"") -> kg | H16: 15 | I16: 191.26 | J16: =IF(OR(H16="",I16=""),"",H16*I16) -> 2868.9 | K16: Ajuste de estoque
A17: 45690 | B17: NF-2025-0014 | C17: Planta Forte Agro | D17: CAN-INS-005 | E17: =IFERROR(VLOOKUP(D17,Itens!$A$2:$E$51,2,FALSE),"") -> Fipronil 250 SC | F17: =IFERROR(VLOOKUP(D17,Itens!$A$2:$E$51,4,FALSE),"") -> Inseticida | G17: =IFERROR(VLOOKUP(D17,Itens!$A$2:$E$51,3,FALSE),"") -> L | H17: 200 | I17: 210.82 | J17: =IF(OR(H17="",I17=""),"",H17*I17) -> 42164 | K17: Ajuste de estoque
A18: 45726 | B18: NF-2025-0042 | C18: CoopCana | D18: CAN-ORG-001 | E18: =IFERROR(VLOOKUP(D18,Itens!$A$2:$E$51,2,FALSE),"") -> Composto orgânico (granulado) | F18: =IFERROR(VLOOKUP(D18,Itens!$A$2:$E$51,4,FALSE),"") -> Organomineral | G18: =IFERROR(VLOOKUP(D18,Itens!$A$2:$E$51,3,FALSE),"") -> kg | H18: 1000 | I18: 1.24 | J18: =IF(OR(H18="",I18=""),"",H18*I18) -> 1240 | K18: Ajuste de estoque
A19: 45743 | B19: NF-2025-0016 | C19: Planta Forte Agro | D19: CAN-NEM-001 | E19: =IFERROR(VLOOKUP(D19,Itens!$A$2:$E$51,2,FALSE),"") -> Fluensulfona 480 EC | F19: =IFERROR(VLOOKUP(D19,Itens!$A$2:$E$51,4,FALSE),"") -> Nematicida | G19: =IFERROR(VLOOKUP(D19,Itens!$A$2:$E$51,3,FALSE),"") -> L | H19: 250 | I19: 540.8 | J19: =IF(OR(H19="",I19=""),"",H19*I19) -> 135200 | K19: Ajuste de estoque
... A24: 45818 | B24: NF-2025-0006 | C24: AgroVale Distribuidora | D24: CAN-HER-006 | E24: =IFERROR(VLOOKUP(D24,Itens!$A$2:$E$51,2,FALSE),"") -> Tebutiuron 500 WG | F24: =IFERROR(VLOOKUP(D24,Itens!$A$2:$E$51,4,FALSE),"") -> Herbicida | G24: =IFERROR(VLOOKUP(D24,Itens!$A$2:$E$51,3,FALSE),"") -> kg | H24: 10 | I24: 74.13 | J24: =IF(OR(H24="",I24=""),"",H24*I24) -> 741.3 | K24: Safra/Tratos
A25: 45836 | B25: NF-2025-0031 | C25: Minas Gesso | D25: CAN-CAL-003 | E25: =IFERROR(VLOOKUP(D25,Itens!$A$2:$E$51,2,FALSE),"") -> Gesso agrícola (sulfato de cálcio) | F25: =IFERROR(VLOOKUP(D25,Itens!$A$2:$E$51,4,FALSE),"") -> Condicionador de solo | G25: =IFERROR(VLOOKUP(D25,Itens!$A$2:$E$51,3,FALSE),"") -> t | H25: 250 | I25: 210.85 | J25: =IF(OR(H25="",I25=""),"",H25*I25) -> 52712.5
A26: 45844 | B26: NF-2025-0008 | C26: Planta Forte Agro | D26: CAN-HER-009 | E26: =IFERROR(VLOOKUP(D26,Itens!$A$2:$E$51,2,FALSE),"") -> Metolacloro 960 EC | F26: =IFERROR(VLOOKUP(D26,Itens!$A$2:$E$51,4,FALSE),"") -> Herbicida | G26: =IFERROR(VLOOKUP(D26,Itens!$A$2:$E$51,3,FALSE),"") -> L | H26: 120 | I26: 57.58 | J26: =IF(OR(H26="",I26=""),"",H26*I26) -> 6909.6 | K26: Compra programada
A27: 45847 | B27: NF-2025-0010 | C27: AgroVale Distribuidora | D27: CAN-INS-001 | E27: =IFERROR(VLOOKUP(D27,Itens!$A$2:$E$51,2,FALSE),"") -> Inseticida – Imidacloprido 200 SL | F27: =IFERROR(VLOOKUP(D27,Itens!$A$2:$E$51,4,FALSE),"") -> Inseticida | G27: =IFERROR(VLOOKUP(D27,Itens!$A$2:$E$51,3,FALSE),"") -> L | H27: 200 | I27: 118.07 | J27: =IF(OR(H27="",I27=""),"",H27*I27) -> 23614
A28: 45856 | B28: NF-2025-0027 | C28: Nutriplan | D28: CAN-FER-010 | E28: =IFERROR(VLOOKUP(D28,Itens!$A$2:$E$51,2,FALSE),"") -> NPK 20-00-20 | F28: =IFERROR(VLOOKUP(D28,Itens!$A$2:$E$51,4,FALSE),"") -> Fertilizante (NPK) | G28: =IFERROR(VLOOKUP(D28,Itens!$A$2:$E$51,3,FALSE),"") -> kg | H28: 20000 | I28: 3.39 | J28: =IF(OR(H28="",I28=""),"",H28*I28) -> 67800 | K28: Reposição
A29: 45862 | B29: NF-2025-0012 | C29: CoopCana | D29: CAN-INS-003 | E29: =IFERROR(VLOOKUP(D29,Itens!$A$2:$E$51,2,FALSE),"") -> Clorantraniliprole 200 SC | F29: =IFERROR(VLOOKUP(D29,Itens!$A$2:$E$51,4,FALSE),"") -> Inseticida | G29: =IFERROR(VLOOKUP(D29,Itens!$A$2:$E$51,3,FALSE),"") -> L | H29: 400 | I29: 623.69 | J29: =IF(OR(H29="",I29=""),"",H29*I29) -> 249476 | K29: Safra/Tratos
A30: 45868 | B30: NF-2025-0019 | C30: CoopCana | D30: CAN-NEM-004 | E30: =IFERROR(VLOOKUP(D30,Itens!$A$2:$E$51,2,FALSE),"") -> Purpureocillium lilacinum | F30: =IFERROR(VLOOKUP(D30,Itens!$A$2:$E$51,4,FALSE),"") -> Nematicida | G30: =IFERROR(VLOOKUP(D30,Itens!$A$2:$E$51,3,FALSE),"") -> kg | H30: 50 | I30: 203.05 | J30: =IF(OR(H30="",I30=""),"",H30*I30) -> 10152.5 | K30: Lote promocional
A31: 45907 | B31: NF-2025-0026 | C31: FertiMinas | D31: CAN-FER-010 | E31: =IFERROR(VLOOKUP(D31,Itens!$A$2:$E$51,2,FALSE),"") -> NPK 20-00-20 | F31: =IFERROR(VLOOKUP(D31,Itens!$A$2:$E$51,4,FALSE),"") -> Fertilizante (NPK) | G31: =IFERROR(VLOOKUP(D31,Itens!$A$2:$E$51,3,FALSE),"") -> kg | H31: 5000 | I31: 3.77 | J31: =IF(OR(H31="",I31=""),"",H31*I31) -> 18850 | K31: Ajuste de estoque
A32: 45922 | B32: NF-2025-0047 | C32: Planta Forte Agro | D32: CAN-ADJ-002 | E32: =IFERROR(VLOOKUP(D32,Itens!$A$2:$E$51,2,FALSE),"") -> Espalhante adesivo não iônico | F32: =IFERROR(VLOOKUP(D32,Itens!$A$2:$E$51,4,FALSE),"") -> Adjuvante | G32: =IFERROR(VLOOKUP(D32,Itens!$A$2:$E$51,3,FALSE),"") -> L | H32: 150 | I32: 36.05 | J32: =IF(OR(H32="",I32=""),"",H32*I32) -> 5407.5
A33: 45943 | B33: NF-2025-0015 | C33: AgroVale Distribuidora | D33: CAN-INS-006 | E33: =IFERROR(VLOOKUP(D33,Itens!$A$2:$E$51,2,FALSE),"") -> Bacillus thuringiensis (Bt) | F33: =IFERROR(VLOOKUP(D33,Itens!$A$2:$E$51,4,FALSE),"") -> Inseticida | G33: =IFERROR(VLOOKUP(D33,Itens!$A$2:$E$51,3,FALSE),"") -> kg | H33: 25 | I33: 170.12 | J33: =IF(OR(H33="",I33=""),"",H33*I33) -> 4253
A34: 45947 | B34: NF-2025-0034 | C34: Nutriplan | D34: CAN-CA-001 | E34: =IFERROR(VLOOKUP(D34,Itens!$A$2:$E$51,2,FALSE),"") -> Fonte de Cálcio – Nitrato de cálcio | F34: =IFERROR(VLOOKUP(D34,Itens!$A$2:$E$51,4,FALSE),"") -> Cálcio | G34: =IFERROR(VLOOKUP(D34,Itens!$A$2:$E$51,3,FALSE),"") -> kg | H34: 10 | I34: 5.5 | J34: =IF(OR(H34="",I34=""),"",H34*I34) -> 55 | K34: Lote promocional
A35: 45958 | B35: NF-2025-0030 | C35: Calcários Serra Azul | D35: CAN-CAL-002 | E35: =IFERROR(VLOOKUP(D35,Itens!$A$2:$E$51,2,FALSE),"") -> Calcário calcítico (PRNT alto) | F35: =IFERROR(VLOOKUP(D35,Itens!$A$2:$E$51,4,FALSE),"") -> Corretivo (Calcário) | G35: =IFERROR(VLOOKUP(D35,Itens!$A$2:$E$51,3,FALSE),"") -> t | H35: 300 | I35: 170.46 | J35: =IF(OR(H35="",I35=""),"",H35*I35) -> 51138 | K35: Reposição
A36: 45971 | B36: NF-2025-0036 | C36: AgroVale Distribuidora | D36: CAN-MIC-002 | E36: =IFERROR(VLOOKUP(D36,Itens!$A$2:$E$51,2,FALSE),"") -> Zinco (Zn) granulado | F36: =IFERROR(VLOOKUP(D36,Itens!$A$2:$E$51,4,FALSE),"") -> Micronutriente | G36: =IFERROR(VLOOKUP(D36,Itens!$A$2:$E$51,3,FALSE),"") -> kg | H36: 80 | I36: 15.06 | J36: =IF(OR(H36="",I36=""),"",H36*I36) -> 1204.8 | K36: Compra programada
A37: 45972 | B37: NF-2025-0038 | C37: Nutriplan | D37: CAN-MIC-004 | E37: =IFERROR(VLOOKUP(D37,Itens!$A$2:$E$51,2,FALSE),"") -> Cobre (Cu) | F37: =IFERROR(VLOOKUP(D37,Itens!$A$2:$E$51,4,FALSE),"") -> Micronutriente | G37: =IFERROR(VLOOKUP(D37,Itens!$A$2:$E$51,3,FALSE),"") -> kg | H37: 80 | I37: 24.34 | J37: =IF(OR(H37="",I37=""),"",H37*I37) -> 1947.2 | K37: Compra programada
A38: 45986 | B38: NF-2025-0021 | C38: FertiMinas | D38: CAN-FER-004 | E38: =IFERROR(VLOOKUP(D38,Itens!$A$2:$E$51,2,FALSE),"") -> Cloreto de potássio (KCl) 60% K2O | F38: =IFERROR(VLOOKUP(D38,Itens!$A$2:$E$51,4,FALSE),"") -> Fertilizante (K) | G38: =IFERROR(VLOOKUP(D38,Itens!$A$2:$E$51,3,FALSE),"") -> kg | H38: 2000 | I38: 3.23 | J38: =IF(OR(H38="",I38=""),"",H38*I38) -> 6460 | K38: Safra/Tratos
A39: 45988 | B39: NF-2025-0040 | C39: BioAgro Insumos | D39: CAN-INO-001 | E39: =IFERROR(VLOOKUP(D39,Itens!$A$2:$E$51,2,FALSE),"") -> Azospirillum brasilense (líquido) | F39: =IFERROR(VLOOKUP(D39,Itens!$A$2:$E$51,4,FALSE),"") -> Inoculante | G39: =IFERROR(VLOOKUP(D39,Itens!$A$2:$E$51,3,FALSE),"") -> L | H39: 50 | I39: 49.18 | J39: =IF(OR(H39="",I39=""),"",H39*I39) -> 2459 | K39: Compra programada
A40: 45991 | B40: NF-2025-0003 | C40: Planta Forte Agro | D40: CAN-HER-003 | E40: =IFERROR(VLOOKUP(D40,Itens!$A$2:$E$51,2,FALSE),"") -> Atrazina 500 SC | F40: =IFERROR(VLOOKUP(D40,Itens!$A$2:$E$51,4,FALSE),"") -> Herbicida | G40: =IFERROR(VLOOKUP(D40,Itens!$A$2:$E$51,3,FALSE),"") -> L | H40: 50 | I40: 24.5 | J40: =IF(OR(H40="",I40=""),"",H40*I40) -> 1225
A41: 45993 | B41: NF-2025-0022 | C41: CoopCana | D41: CAN-FER-004 | E41: =IFERROR(VLOOKUP(D41,Itens!$A$2:$E$51,2,FALSE),"") -> Cloreto de potássio (KCl) 60% K2O | F41: =IFERROR(VLOOKUP(D41,Itens!$A$2:$E$51,4,FALSE),"") -> Fertilizante (K) | G41: =IFERROR(VLOOKUP(D41,Itens!$A$2:$E$51,3,FALSE),"") -> kg | H41: 5000 | I41: 2.84 | J41: =IF(OR(H41="",I41=""),"",H41*I41) -> 14200 | K41: Reposição
A42: 46009 | B42: NF-2025-0043 | C42: Nutriplan | D42: CAN-ORG-001 | E42: =IFERROR(VLOOKUP(D42,Itens!$A$2:$E$51,2,FALSE),"") -> Composto orgânico (granulado) | F42: =IFERROR(VLOOKUP(D42,Itens!$A$2:$E$51,4,FALSE),"") -> Organomineral | G42: =IFERROR(VLOOKUP(D42,Itens!$A$2:$E$51,3,FALSE),"") -> kg | H42: 8000 | I42: 1.15 | J42: =IF(OR(H42="",I42=""),"",H42*I42) -> 9200
A43: 46017 | B43: NF-2025-0023 | C43: FertiMinas | D43: CAN-FER-005 | E43: =IFERROR(VLOOKUP(D43,Itens!$A$2:$E$51,2,FALSE),"") -> Sulfato de potássio 50% K2O | F43: =IFERROR(VLOOKUP(D43,Itens!$A$2:$E$51,4,FALSE),"") -> Fertilizante (K/S) | G43: =IFERROR(VLOOKUP(D43,Itens!$A$2:$E$51,3,FALSE),"") -> kg | H43: 12000 | I43: 4.84 | J43: =IF(OR(H43="",I43=""),"",H43*I43) -> 58080 | K43: Compra programada
A44: 46023 | B44: NF-2026-0020 | C44: Nutriplan | D44: CAN-FER-002 | E44: =IFERROR(VLOOKUP(D44,Itens!$A$2:$E$51,2,FALSE),"") -> Sulfato de amônio 21% N + 24% S | F44: =IFERROR(VLOOKUP(D44,Itens!$A$2:$E$51,4,FALSE),"") -> Fertilizante (N/S) | G44: =IFERROR(VLOOKUP(D44,Itens!$A$2:$E$51,3,FALSE),"") -> kg | H44: 12000 | I44: 1.69 | J44: =IF(OR(H44="",I44=""),"",H44*I44) -> 20280 | K44: Ajuste de estoque
...

Sheet Saidas
A1: Data | B1: Documento | C1: Destino/Área | D1: COD_ID | E1: Descrição | F1: Familia | G1: Unidade | H1: Quantidade | I1: Preço Unitário (R$) | J1: Valor Total (R$) | K1: Centro de custo | L1: Observações
A2: 45474 | B2: RM-2024-0024 | C2: Fazenda Boa Esperança - Talhão 09 | D2: CAN-NEM-001 | E2: =IFERROR(VLOOKUP(D2,Itens!$A$2:$E$51,2,FALSE),"") -> Fluensulfona 480 EC | F2: =IFERROR(VLOOKUP(D2,Itens!$A$2:$E$51,4,FALSE),"") -> Nematicida | G2: =IFERROR(VLOOKUP(D2,Itens!$A$2:$E$51,3,FALSE),"") -> L | H2: 42.05 | I2: =VLOOKUP(Tabela3[[#This Row],[COD_ID]],Itens!A:E,5,0) -> 500 | J2: =Tabela3[[#This Row],[Preço Unitário (R$)]]*Tabela3[[#This Row],[Quantidade]] -> 21025 | K2: Controle de Plantas Daninhas
A3: 45483 | B3: RM-2024-0007 | C3: Fazenda Santa Rita - Talhão 07 | D3: CAN-HER-003 | E3: =IFERROR(VLOOKUP(D3,Itens!$A$2:$E$51,2,FALSE),"") -> Atrazina 500 SC | F3: =IFERROR(VLOOKUP(D3,Itens!$A$2:$E$51,4,FALSE),"") -> Herbicida | G3: =IFERROR(VLOOKUP(D3,Itens!$A$2:$E$51,3,FALSE),"") -> L | H3: 12.14 | I3: =VLOOKUP(Tabela3[[#This Row],[COD_ID]],Itens!A:E,5,0) -> 24 | J3: =Tabela3[[#This Row],[Preço Unitário (R$)]]*Tabela3[[#This Row],[Quantidade]] -> 291.36 | K3: Adubação | L3: Operação de campo
A4: 45486 | B4: RM-2024-0057 | C4: Fazenda Serra Verde - Talhão 11 | D4: CAN-MIC-005 | E4: =IFERROR(VLOOKUP(D4,Itens!$A$2:$E$51,2,FALSE),"") -> Mistura de micronutrientes (B+Zn+Mn+Cu) | F4: =IFERROR(VLOOKUP(D4,Itens!$A$2:$E$51,4,FALSE),"") -> Micronutriente | G4: =IFERROR(VLOOKUP(D4,Itens!$A$2:$E$51,3,FALSE),"") -> kg | H4: 72.82 | I4: =VLOOKUP(Tabela3[[#This Row],[COD_ID]],Itens!A:E,5,0) -> 18 | J4: =Tabela3[[#This Row],[Preço Unitário (R$)]]*Tabela3[[#This Row],[Quantidade]] -> 1310.76 | K4: Controle de Plantas Daninhas | L4: Aplicação programada
A5: 45500 | B5: RM-2024-0053 | C5: Fazenda Boa Esperança - Talhão 09 | D5: CAN-MIC-003 | E5: =IFERROR(VLOOKUP(D5,Itens!$A$2:$E$51,2,FALSE),"") -> Manganês (Mn) | F5: =IFERROR(VLOOKUP(D5,Itens!$A$2:$E$51,4,FALSE),"") -> Micronutriente | G5: =IFERROR(VLOOKUP(D5,Itens!$A$2:$E$51,3,FALSE),"") -> kg | H5: 8.45 | I5: =VLOOKUP(Tabela3[[#This Row],[COD_ID]],Itens!A:E,5,0) -> 10 | J5: =Tabela3[[#This Row],[Preço Unitário (R$)]]*Tabela3[[#This Row],[Quantidade]] -> 84.5 | K5: Controle de Plantas Daninhas | L5: Ajuste
A6: 45501 | B6: RM-2024-0044 | C6: Fazenda Serra Verde - Talhão 11 | D6: CAN-CAL-004 | E6: =IFERROR(VLOOKUP(D6,Itens!$A$2:$E$51,2,FALSE),"") -> Cal virgem agrícola | F6: =IFERROR(VLOOKUP(D6,Itens!$A$2:$E$51,4,FALSE),"") -> Corretivo (Calagem) | G6: =IFERROR(VLOOKUP(D6,Itens!$A$2:$E$51,3,FALSE),"") -> kg | H6: 330 | I6: =VLOOKUP(Tabela3[[#This Row],[COD_ID]],Itens!A:E,5,0) -> 1.2 | J6: =Tabela3[[#This Row],[Preço Unitário (R$)]]*Tabela3[[#This Row],[Quantidade]] -> 396 | K6: Plantio
A7: 45515 | B7: RM-2024-0049 | C7: Fazenda Santa Rita - Talhão 01 | D7: CAN-MIC-002 | E7: =IFERROR(VLOOKUP(D7,Itens!$A$2:$E$51,2,FALSE),"") -> Zinco (Zn) granulado | F7: =IFERROR(VLOOKUP(D7,Itens!$A$2:$E$51,4,FALSE),"") -> Micronutriente | G7: =IFERROR(VLOOKUP(D7,Itens!$A$2:$E$51,3,FALSE),"") -> kg | H7: 31.69 | I7: =VLOOKUP(Tabela3[[#This Row],[COD_ID]],Itens!A:E,5,0) -> 14 | J7: =Tabela3[[#This Row],[Preço Unitário (R$)]]*Tabela3[[#This Row],[Quantidade]] -> 443.66 | K7: Correção do Solo | L7: Aplicação programada
A8: 45553 | B8: RM-2024-0036 | C8: Fazenda Boa Esperança - Talhão 09 | D8: CAN-FER-006 | E8: =IFERROR(VLOOKUP(D8,Itens!$A$2:$E$51,2,FALSE),"") -> MAP (Monoamônio Fosfato) 11-52-0 | F8: =IFERROR(VLOOKUP(D8,Itens!$A$2:$E$51,4,FALSE),"") -> Fosfatado | G8: =IFERROR(VLOOKUP(D8,Itens!$A$2:$E$51,3,FALSE),"") -> kg | H8: 430 | I8: =VLOOKUP(Tabela3[[#This Row],[COD_ID]],Itens!A:E,5,0) -> 4.2 | J8: =Tabela3[[#This Row],[Preço Unitário (R$)]]*Tabela3[[#This Row],[Quantidade]] -> 1806 | K8: Correção do Solo | L8: Manutenção
A9: 45561 | B9: RM-2024-0064 | C9: Fazenda Boa Esperança - Talhão 03 | D9: CAN-ORG-002 | E9: =IFERROR(VLOOKUP(D9,Itens!$A$2:$E$51,2,FALSE),"") -> Fertilizante organomineral NPK (formulação padrão) | F9: =IFERROR(VLOOKUP(D9,Itens!$A$2:$E$51,4,FALSE),"") -> Organomineral | G9: =IFERROR(VLOOKUP(D9,Itens!$A$2:$E$51,3,FALSE),"") -> kg | H9: 6080 | I9: =VLOOKUP(Tabela3[[#This Row],[COD_ID]],Itens!A:E,5,0) -> 2.8 | J9: =Tabela3[[#This Row],[Preço Unitário (R$)]]*Tabela3[[#This Row],[Quantidade]] -> 17024 | K9: Tratos Culturais | L9: Ajuste
A10: 45579 | B10: RM-2024-0010 | C10: Fazenda Serra Verde - Talhão 05 | D10: CAN-HER-004 | E10: =IFERROR(VLOOKUP(D10,Itens!$A$2:$E$51,2,FALSE),"") -> Hexazinona 250 SC | F10: =IFERROR(VLOOKUP(D10,Itens!$A$2:$E$51,4,FALSE),"") -> Herbicida | G10: =IFERROR(VLOOKUP(D10,Itens!$A$2:$E$51,3,FALSE),"") -> L | H10: 27.47 | I10: =VLOOKUP(Tabela3[[#This Row],[COD_ID]],Itens!A:E,5,0) -> 110 | J10: =Tabela3[[#This Row],[Preço Unitário (R$)]]*Tabela3[[#This Row],[Quantidade]] -> 3021.7 | K10: Plantio | L10: Ajuste
A11: 45591 | B11: RM-2024-0052 | C11: Fazenda Santa Rita - Talhão 12 | D11: CAN-MIC-003 | E11: =IFERROR(VLOOKUP(D11,Itens!$A$2:$E$51,2,FALSE),"") -> Manganês (Mn) | F11: =IFERROR(VLOOKUP(D11,Itens!$A$2:$E$51,4,FALSE),"") -> Micronutriente | G11: =IFERROR(VLOOKUP(D11,Itens!$A$2:$E$51,3,FALSE),"") -> kg | H11: 23.4 | I11: =VLOOKUP(Tabela3[[#This Row],[COD_ID]],Itens!A:E,5,0) -> 10 | J11: =Tabela3[[#This Row],[Preço Unitário (R$)]]*Tabela3[[#This Row],[Quantidade]] -> 234 | K11: Adubação
A12: 45592 | B12: RM-2024-0002 | C12: Fazenda Santa Rita - Talhão 07 | D12: CAN-HER-001 | E12: =IFERROR(VLOOKUP(D12,Itens!$A$2:$E$51,2,FALSE),"") -> Glifosato 480 SL | F12: =IFERROR(VLOOKUP(D12,Itens!$A$2:$E$51,4,FALSE),"") -> Herbicida | G12: =IFERROR(VLOOKUP(D12,Itens!$A$2:$E$51,3,FALSE),"") -> L | H12: 22.71 | I12: =VLOOKUP(Tabela3[[#This Row],[COD_ID]],Itens!A:E,5,0) -> 22 | J12: =Tabela3[[#This Row],[Preço Unitário (R$)]]*Tabela3[[#This Row],[Quantidade]] -> 499.62 | K12: Correção do Solo | L12: Manutenção
A13: 45596 | B13: RM-2024-0070 | C13: Oficina/Manutenção | D13: CAN-ADJ-002 | E13: =IFERROR(VLOOKUP(D13,Itens!$A$2:$E$51,2,FALSE),"") -> Espalhante adesivo não iônico | F13: =IFERROR(VLOOKUP(D13,Itens!$A$2:$E$51,4,FALSE),"") -> Adjuvante | G13: =IFERROR(VLOOKUP(D13,Itens!$A$2:$E$51,3,FALSE),"") -> L | H13: 48.97 | I13: =VLOOKUP(Tabela3[[#This Row],[COD_ID]],Itens!A:E,5,0) -> 35 | J13: =Tabela3[[#This Row],[Preço Unitário (R$)]]*Tabela3[[#This Row],[Quantidade]] -> 1713.95 | K13: Tratos Culturais | L13: Operação de campo
A14: 45597 | B14: RM-2024-0055 | C14: Pátio - Apoio | D14: CAN-MIC-005 | E14: =IFERROR(VLOOKUP(D14,Itens!$A$2:$E$51,2,FALSE),"") -> Mistura de micronutrientes (B+Zn+Mn+Cu) | F14: =IFERROR(VLOOKUP(D14,Itens!$A$2:$E$51,4,FALSE),"") -> Micronutriente | G14: =IFERROR(VLOOKUP(D14,Itens!$A$2:$E$51,3,FALSE),"") -> kg | H14: 93.95 | I14: =VLOOKUP(Tabela3[[#This Row],[COD_ID]],Itens!A:E,5,0) -> 18 | J14: =Tabela3[[#This Row],[Preço Unitário (R$)]]*Tabela3[[#This Row],[Quantidade]] -> 1691.1 | K14: Controle de Pragas
A15: 45612 | B15: RM-2024-0045 | C15: Viveiro/Estufa - Área Experimental | D15: CAN-CA-001 | E15: =IFERROR(VLOOKUP(D15,Itens!$A$2:$E$51,2,FALSE),"") -> Fonte de Cálcio – Nitrato de cálcio | F15: =IFERROR(VLOOKUP(D15,Itens!$A$2:$E$51,4,FALSE),"") -> Cálcio | G15: =IFERROR(VLOOKUP(D15,Itens!$A$2:$E$51,3,FALSE),"") -> kg | H15: 1.19 | I15: =VLOOKUP(Tabela3[[#This Row],[COD_ID]],Itens!A:E,5,0) -> 5.5 | J15: =Tabela3[[#This Row],[Preço Unitário (R$)]]*Tabela3[[#This Row],[Quantidade]] -> 6.545 | K15: Controle de Pragas | L15: Ajuste
A16: 45615 | B16: RM-2024-0037 | C16: Fazenda Santa Rita - Talhão 12 | D16: CAN-FER-009 | E16: =IFERROR(VLOOKUP(D16,Itens!$A$2:$E$51,2,FALSE),"") -> Superfosfato triplo (TSP) | F16: =IFERROR(VLOOKUP(D16,Itens!$A$2:$E$51,4,FALSE),"") -> Fosfatado | G16: =IFERROR(VLOOKUP(D16,Itens!$A$2:$E$51,3,FALSE),"") -> kg | H16: 15930 | I16: =VLOOKUP(Tabela3[[#This Row],[COD_ID]],Itens!A:E,5,0) -> 3.2 | J16: =Tabela3[[#This Row],[Preço Unitário (R$)]]*Tabela3[[#This Row],[Quantidade]] -> 50976 | K16: Correção do Solo | L16: Ajuste
A17: 45630 | B17: RM-2024-0050 | C17: Fazenda Boa Esperança - Talhão 03 | D17: CAN-MIC-002 | E17: =IFERROR(VLOOKUP(D17,Itens!$A$2:$E$51,2,FALSE),"") -> Zinco (Zn) granulado | F17: =IFERROR(VLOOKUP(D17,Itens!$A$2:$E$51,4,FALSE),"") -> Micronutriente | G17: =IFERROR(VLOOKUP(D17,Itens!$A$2:$E$51,3,FALSE),"") -> kg | H17: 7.93 | I17: =VLOOKUP(Tabela3[[#This Row],[COD_ID]],Itens!A:E,5,0) -> 14 | J17: =Tabela3[[#This Row],[Preço Unitário (R$)]]*Tabela3[[#This Row],[Quantidade]] -> 111.02 | K17: Tratos Culturais | L17: Aplicação programada
A18: 45630 | B18: RM-2024-0058 | C18: Fazenda Serra Verde - Talhão 11 | D18: CAN-INO-001 | E18: =IFERROR(VLOOKUP(D18,Itens!$A$2:$E$51,2,FALSE),"") -> Azospirillum brasilense (líquido) | F18: =IFERROR(VLOOKUP(D18,Itens!$A$2:$E$51,4,FALSE),"") -> Inoculante | G18: =IFERROR(VLOOKUP(D18,Itens!$A$2:$E$51,3,FALSE),"") -> L | H18: 8.04 | I18: =VLOOKUP(Tabela3[[#This Row],[COD_ID]],Itens!A:E,5,0) -> 45 | J18: =Tabela3[[#This Row],[Preço Unitário (R$)]]*Tabela3[[#This Row],[Quantidade]] -> 361.8 | K18: Plantio | L18: Manutenção
A19: 45636 | B19: RM-2024-0034 | C19: Viveiro/Estufa - Área Experimental | D19: CAN-FER-005 | E19: =IFERROR(VLOOKUP(D19,Itens!$A$2:$E$51,2,FALSE),"") -> Sulfato de potássio 50% K2O | F19: =IFERROR(VLOOKUP(D19,Itens!$A$2:$E$51,4,FALSE),"") -> Fertilizante (K/S) | G19: =IFERROR(VLOOKUP(D19,Itens!$A$2:$E$51,3,FALSE),"") -> kg | H19: 3890 | I19: =VLOOKUP(Tabela3[[#This Row],[COD_ID]],Itens!A:E,5,0) -> 4.8 | J19: =Tabela3[[#This Row],[Preço Unitário (R$)]]*Tabela3[[#This Row],[Quantidade]] -> 18672 | K19: Controle de Plantas Daninhas | L19: Manutenção
A20: 45639 | B20: RM-2024-0006 | C20: Viveiro/Estufa - Área Experimental | D20: CAN-HER-003 | E20: =IFERROR(VLOOKUP(D20,Itens!$A$2:$E$51,2,FALSE),"") -> Atrazina 500 SC | F20: =IFERROR(VLOOKUP(D20,Itens!$A$2:$E$51,4,FALSE),"") -> Herbicida | G20: =IFERROR(VLOOKUP(D20,Itens!$A$2:$E$51,3,FALSE),"") -> L | H20: 8.63 | I20: =VLOOKUP(Tabela3[[#This Row],[COD_ID]],Itens!A:E,5,0) -> 24 | J20: =Tabela3[[#This Row],[Preço Unitário (R$)]]*Tabela3[[#This Row],[Quantidade]] -> 207.12 | K20: Controle de Plantas Daninhas
A21: 45640 | B21: RM-2024-0011 | C21: Fazenda Santa Rita - Talhão 12 | D21: CAN-HER-005 | E21: =IFERROR(VLOOKUP(D21,Itens!$A$2:$E$51,2,FALSE),"") -> Diuron 500 SC | F21: =IFERROR(VLOOKUP(D21,Itens!$A$2:$E$51,4,FALSE),"") -> Herbicida | G21: =IFERROR(VLOOKUP(D21,Itens!$A$2:$E$51,3,FALSE),"") -> L | H21: 181.18 | I21: =VLOOKUP(Tabela3[[#This Row],[COD_ID]],Itens!A:E,5,0) -> 30 | J21: =Tabela3[[#This Row],[Preço Unitário (R$)]]*Tabela3[[#This Row],[Quantidade]] -> 5435.4 | K21: Controle de Plantas Daninhas | L21: Aplicação programada
A22: 45643 | B22: RM-2024-0043 | C22: Viveiro/Estufa - Área Experimental | D22: CAN-CAL-004 | E22: =IFERROR(VLOOKUP(D22,Itens!$A$2:$E$51,2,FALSE),"") -> Cal virgem agrícola | F22: =IFERROR(VLOOKUP(D22,Itens!$A$2:$E$51,4,FALSE),"") -> Corretivo (Calagem) | G22: =IFERROR(VLOOKUP(D22,Itens!$A$2:$E$51,3,FALSE),"") -> kg | H22: 360 | I22: =VLOOKUP(Tabela3[[#This Row],[COD_ID]],Itens!A:E,5,0) -> 1.2 | J22: =Tabela3[[#This Row],[Preço Unitário (R$)]]*Tabela3[[#This Row],[Quantidade]] -> 432 | K22: Plantio
A23: 45660 | B23: RM-2025-0062 | C23: Viveiro/Estufa - Área Experimental | D23: CAN-ORG-001 | E23: =IFERROR(VLOOKUP(D23,Itens!$A$2:$E$51,2,FALSE),"") -> Composto orgânico (granulado) | F23: =IFERROR(VLOOKUP(D23,Itens!$A$2:$E$51,4,FALSE),"") -> Organomineral | G23: =IFERROR(VLOOKUP(D23,Itens!$A$2:$E$51,3,FALSE),"") -> kg | H23: 1690 | I23: =VLOOKUP(Tabela3[[#This Row],[COD_ID]],Itens!A:E,5,0) -> 1.2 | J23: =Tabela3[[#This Row],[Preço Unitário (R$)]]*Tabela3[[#This Row],[Quantidade]] -> 2028 | K23: Controle de Pragas | L23: Manutenção
A24: 45675 | B24: RM-2025-0020 | C24: Fazenda Serra Verde - Talhão 05 | D24: CAN-INS-005 | E24: =IFERROR(VLOOKUP(D24,Itens!$A$2:$E$51,2,FALSE),"") -> Fipronil 250 SC | F24: =IFERROR(VLOOKUP(D24,Itens!$A$2:$E$51,4,FALSE),"") -> Inseticida | G24: =IFERROR(VLOOKUP(D24,Itens!$A$2:$E$51,3,FALSE),"") -> L | H24: 62.23 | I24: =VLOOKUP(Tabela3[[#This Row],[COD_ID]],Itens!A:E,5,0) -> 220 | J24: =Tabela3[[#This Row],[Preço Unitário (R$)]]*Tabela3[[#This Row],[Quantidade]] -> 13690.6 | K24: Tratos Culturais | L24: Manutenção
A25: 45677 | B25: RM-2025-0054 | C25: Fazenda Santa Rita - Talhão 07 | D25: CAN-MIC-003 | E25: =IFERROR(VLOOKUP(D25,Itens!$A$2:$E$51,2,FALSE),"") -> Manganês (Mn) | F25: =IFERROR(VLOOKUP(D25,Itens!$A$2:$E$51,4,FALSE),"") -> Micronutriente | G25: =IFERROR(VLOOKUP(D25,Itens!$A$2:$E$51,3,FALSE),"") -> kg | H25: 11.54 | I25: =VLOOKUP(Tabela3[[#This Row],[COD_ID]],Itens!A:E,5,0) -> 10 | J25: =Tabela3[[#This Row],[Preço Unitário (R$)]]*Tabela3[[#This Row],[Quantidade]] -> 115.4 | K25: Plantio | L25: Operação de campo
A26: 45697 | B26: RM-2025-0051 | C26: Viveiro/Estufa - Área Experimental | D26: CAN-MIC-002 | E26: =IFERROR(VLOOKUP(D26,Itens!$A$2:$E$51,2,FALSE),"") -> Zinco (Zn) granulado | F26: =IFERROR(VLOOKUP(D26,Itens!$A$2:$E$51,4,FALSE),"") -> Micronutriente | G26: =IFERROR(VLOOKUP(D26,Itens!$A$2:$E$51,3,FALSE),"") -> kg | H26: 19.63 | I26: =VLOOKUP(Tabela3[[#This Row],[COD_ID]],Itens!A:E,5,0) -> 14 | J26: =Tabela3[[#This Row],[Preço Unitário (R$)]]*Tabela3[[#This Row],[Quantidade]] -> 274.82 | K26: Tratos Culturais | L26: Manutenção
A27: 45698 | B27: RM-2025-0042 | C27: Fazenda Boa Esperança - Talhão 09 | D27: CAN-CAL-002 | E27: =IFERROR(VLOOKUP(D27,Itens!$A$2:$E$51,2,FALSE),"") -> Calcário calcítico (PRNT alto) | F27: =IFERROR(VLOOKUP(D27,Itens!$A$2:$E$51,4,FALSE),"") -> Corretivo (Calcário) | G27: =IFERROR(VLOOKUP(D27,Itens!$A$2:$E$51,3,FALSE),"") -> t | H27: 83 | I27: =VLOOKUP(Tabela3[[#This Row],[COD_ID]],Itens!A:E,5,0) -> 160 | J27: =Tabela3[[#This Row],[Preço Unitário (R$)]]*Tabela3[[#This Row],[Quantidade]] -> 13280 | K27: Controle de Plantas Daninhas | L27: Ajuste
A28: 45702 | B28: RM-2025-0014 | C28: Fazenda Santa Rita - Talhão 01 | D28: CAN-HER-010 | E28: =IFERROR(VLOOKUP(D28,Itens!$A$2:$E$51,2,FALSE),"") -> MSMA (concentrado solúvel) | F28: =IFERROR(VLOOKUP(D28,Itens!$A$2:$E$51,4,FALSE),"") -> Herbicida | G28: =IFERROR(VLOOKUP(D28,Itens!$A$2:$E$51,3,FALSE),"") -> L | H28: 62.98 | I28: =VLOOKUP(Tabela3[[#This Row],[COD_ID]],Itens!A:E,5,0) -> 45 | J28: =Tabela3[[#This Row],[Preço Unitário (R$)]]*Tabela3[[#This Row],[Quantidade]] -> 2834.1 | K28: Tratos Culturais | L28: Operação de campo
A29: 45704 | B29: RM-2025-0028 | C29: Fazenda Boa Esperança - Talhão 03 | D29: CAN-NEM-002 | E29: =IFERROR(VLOOKUP(D29,Itens!$A$2:$E$51,2,FALSE),"") -> Abamectina 18 EC | F29: =IFERROR(VLOOKUP(D29,Itens!$A$2:$E$51,4,FALSE),"") -> Nematicida | G29: =IFERROR(VLOOKUP(D29,Itens!$A$2:$E$51,3,FALSE),"") -> L | H29: 21.9 | I29: =VLOOKUP(Tabela3[[#This Row],[COD_ID]],Itens!A:E,5,0) -> 220 | J29: =Tabela3[[#This Row],[Preço Unitário (R$)]]*Tabela3[[#This Row],[Quantidade]] -> 4818 | K29: Adubação | L29: Operação de campo
A30: 45725 | B30: RM-2025-0060 | C30: Fazenda Santa Rita - Talhão 07 | D30: CAN-INO-002 | E30: =IFERROR(VLOOKUP(D30,Itens!$A$2:$E$51,2,FALSE),"") -> Bacillus spp. promotor de crescimento | F30: =IFERROR(VLOOKUP(D30,Itens!$A$2:$E$51,4,FALSE),"") -> Inoculante | G30: =IFERROR(VLOOKUP(D30,Itens!$A$2:$E$51,3,FALSE),"") -> kg | H30: 12.94 | I30: =VLOOKUP(Tabela3[[#This Row],[COD_ID]],Itens!A:E,5,0) -> 120 | J30: =Tabela3[[#This Row],[Preço Unitário (R$)]]*Tabela3[[#This Row],[Quantidade]] -> 1552.8 | K30: Controle de Plantas Daninhas | L30: Operação de campo
A31: 45728 | B31: RM-2025-0012 | C31: Fazenda Boa Esperança - Talhão 09 | D31: CAN-HER-007 | E31: =IFERROR(VLOOKUP(D31,Itens!$A$2:$E$51,2,FALSE),"") -> Imazapic 700 WG | F31: =IFERROR(VLOOKUP(D31,Itens!$A$2:$E$51,4,FALSE),"") -> Herbicida | G31: =IFERROR(VLOOKUP(D31,Itens!$A$2:$E$51,3,FALSE),"") -> kg | H31: 11.03 | I31: =VLOOKUP(Tabela3[[#This Row],[COD_ID]],Itens!A:E,5,0) -> 320 | J31: =Tabela3[[#This Row],[Preço Unitário (R$)]]*Tabela3[[#This Row],[Quantidade]] -> 3529.6 | K31: Tratos Culturais | L31: Aplicação programada
A32: 45731 | B32: RM-2025-0069 | C32: Fazenda Boa Esperança - Talhão 03 | D32: CAN-ADJ-002 | E32: =IFERROR(VLOOKUP(D32,Itens!$A$2:$E$51,2,FALSE),"") -> Espalhante adesivo não iônico | F32: =IFERROR(VLOOKUP(D32,Itens!$A$2:$E$51,4,FALSE),"") -> Adjuvante | G32: =IFERROR(VLOOKUP(D32,Itens!$A$2:$E$51,3,FALSE),"") -> L | H32: 19.64 | I32: =VLOOKUP(Tabela3[[#This Row],[COD_ID]],Itens!A:E,5,0) -> 35 | J32: =Tabela3[[#This Row],[Preço Unitário (R$)]]*Tabela3[[#This Row],[Quantidade]] -> 687.4 | K32: Correção do Solo | L32: Manutenção
A33: 45745 | B33: RM-2025-0017 | C33: Fazenda Santa Rita - Talhão 01 | D33: CAN-INS-002 | E33: =IFERROR(VLOOKUP(D33,Itens!$A$2:$E$51,2,FALSE),"") -> Tiametoxam 250 WG | F33: =IFERROR(VLOOKUP(D33,Itens!$A$2:$E$51,4,FALSE),"") -> Inseticida | G33: =IFERROR(VLOOKUP(D33,Itens!$A$2:$E$51,3,FALSE),"") -> kg | H33: 2.55 | I33: =VLOOKUP(Tabela3[[#This Row],[COD_ID]],Itens!A:E,5,0) -> 400 | J33: =Tabela3[[#This Row],[Preço Unitário (R$)]]*Tabela3[[#This Row],[Quantidade]] -> 1020 | K33: Controle de Plantas Daninhas | L33: Manutenção
A34: 45759 | B34: RM-2025-0015 | C34: Fazenda Serra Verde - Talhão 05 | D34: CAN-INS-001 | E34: =IFERROR(VLOOKUP(D34,Itens!$A$2:$E$51,2,FALSE),"") -> Inseticida – Imidacloprido 200 SL | F34: =IFERROR(VLOOKUP(D34,Itens!$A$2:$E$51,4,FALSE),"") -> Inseticida | G34: =IFERROR(VLOOKUP(D34,Itens!$A$2:$E$51,3,FALSE),"") -> L | H34: 97.86 | I34: =VLOOKUP(Tabela3[[#This Row],[COD_ID]],Itens!A:E,5,0) -> 120 | J34: =Tabela3[[#This Row],[Preço Unitário (R$)]]*Tabela3[[#This Row],[Quantidade]] -> 11743.2 | K34: Tratos Culturais
A35: 45760 | B35: RM-2025-0063 | C35: Pátio - Apoio | D35: CAN-ORG-001 | E35: =IFERROR(VLOOKUP(D35,Itens!$A$2:$E$51,2,FALSE),"") -> Composto orgânico (granulado) | F35: =IFERROR(VLOOKUP(D35,Itens!$A$2:$E$51,4,FALSE),"") -> Organomineral | G35: =IFERROR(VLOOKUP(D35,Itens!$A$2:$E$51,3,FALSE),"") -> kg | H35: 3690 | I35: =VLOOKUP(Tabela3[[#This Row],[COD_ID]],Itens!A:E,5,0) -> 1.2 | J35: =Tabela3[[#This Row],[Preço Unitário (R$)]]*Tabela3[[#This Row],[Quantidade]] -> 4428 | K35: Tratos Culturais | L35: Manutenção
A36: 45762 | B36: RM-2025-0003 | C36: Pátio - Apoio | D36: CAN-HER-001 | E36: =IFERROR(VLOOKUP(D36,Itens!$A$2:$E$51,2,FALSE),"") -> Glifosato 480 SL | F36: =IFERROR(VLOOKUP(D36,Itens!$A$2:$E$51,4,FALSE),"") -> Herbicida | G36: =IFERROR(VLOOKUP(D36,Itens!$A$2:$E$51,3,FALSE),"") -> L | H36: 25.34 | I36: =VLOOKUP(Tabela3[[#This Row],[COD_ID]],Itens!A:E,5,0) -> 22 | J36: =Tabela3[[#This Row],[Preço Unitário (R$)]]*Tabela3[[#This Row],[Quantidade]] -> 557.48 | K36: Correção do Solo | L36: Manutenção
A37: 45775 | B37: RM-2025-0066 | C37: Fazenda Boa Esperança - Talhão 03 | D37: CAN-ADJ-001 | E37: =IFERROR(VLOOKUP(D37,Itens!$A$2:$E$51,2,FALSE),"") -> Óleo mineral emulsionável | F37: =IFERROR(VLOOKUP(D37,Itens!$A$2:$E$51,4,FALSE),"") -> Adjuvante | G37: =IFERROR(VLOOKUP(D37,Itens!$A$2:$E$51,3,FALSE),"") -> L | H37: 13.33 | I37: =VLOOKUP(Tabela3[[#This Row],[COD_ID]],Itens!A:E,5,0) -> 20 | J37: =Tabela3[[#This Row],[Preço Unitário (R$)]]*Tabela3[[#This Row],[Quantidade]] -> 266.6 | K37: Correção do Solo | L37: Manutenção
A38: 45780 | B38: RM-2025-0001 | C38: Fazenda Santa Rita - Talhão 07 | D38: CAN-HER-001 | E38: =IFERROR(VLOOKUP(D38,Itens!$A$2:$E$51,2,FALSE),"") -> Glifosato 480 SL | F38: =IFERROR(VLOOKUP(D38,Itens!$A$2:$E$51,4,FALSE),"") -> Herbicida | G38: =IFERROR(VLOOKUP(D38,Itens!$A$2:$E$51,3,FALSE),"") -> L | H38: 54.54 | I38: =VLOOKUP(Tabela3[[#This Row],[COD_ID]],Itens!A:E,5,0) -> 22 | J38: =Tabela3[[#This Row],[Preço Unitário (R$)]]*Tabela3[[#This Row],[Quantidade]] -> 1199.88 | K38: Correção do Solo | L38: Manutenção
A39: 45790 | B39: RM-2025-0022 | C39: Fazenda Serra Verde - Talhão 11 | D39: CAN-INS-005 | E39: =IFERROR(VLOOKUP(D39,Itens!$A$2:$E$51,2,FALSE),"") -> Fipronil 250 SC | F39: =IFERROR(VLOOKUP(D39,Itens!$A$2:$E$51,4,FALSE),"") -> Inseticida | G39: =IFERROR(VLOOKUP(D39,Itens!$A$2:$E$51,3,FALSE),"") -> L | H39: 54.37 | I39: =VLOOKUP(Tabela3[[#This Row],[COD_ID]],Itens!A:E,5,0) -> 220 | J39: =Tabela3[[#This Row],[Preço Unitário (R$)]]*Tabela3[[#This Row],[Quantidade]] -> 11961.4 | K39: Controle de Pragas | L39: Ajuste
A40: 45795 | B40: RM-2025-0018 | C40: Fazenda Serra Verde - Talhão 11 | D40: CAN-INS-002 | E40: =IFERROR(VLOOKUP(D40,Itens!$A$2:$E$51,2,FALSE),"") -> Tiametoxam 250 WG | F40: =IFERROR(VLOOKUP(D40,Itens!$A$2:$E$51,4,FALSE),"") -> Inseticida | G40: =IFERROR(VLOOKUP(D40,Itens!$A$2:$E$51,3,FALSE),"") -> kg | H40: 6.47 | I40: =VLOOKUP(Tabela3[[#This Row],[COD_ID]],Itens!A:E,5,0) -> 400 | J40: =Tabela3[[#This Row],[Preço Unitário (R$)]]*Tabela3[[#This Row],[Quantidade]] -> 2588 | K40: Plantio
...

Sheet Pedidos_Compra
A1: Nº Pedido | B1: Data Pedido | C1: Fornecedor | D1: COD_ID | E1: Descrição | F1: Familia | G1: Unidade | H1: Qtde Pedida | I1: Qtde Recebida | J1: Saldo Aberto | K1: Recebidos (%) | L1: Preço Unitário (R$) | M1: Valor Aberto (R$) | N1: Previsão Entrega | O1: Status
A2: PC-2025-0006 | B2: 46010 | C2: CoopCana | D2: CAN-NEM-001 | E2: =IFERROR(VLOOKUP(D2,Itens!$A$2:$E$51,2,FALSE),"") -> Fluensulfona 480 EC | F2: =IFERROR(VLOOKUP(D2,Itens!$A$2:$E$51,4,FALSE),"") -> Nematicida | G2: =IFERROR(VLOOKUP(D2,Itens!$A$2:$E$51,3,FALSE),"") -> L | H2: 80 | I2: 21.57 | J2: =IF(H2="","",MAX(0,H2-IF(I2="",0,I2))) -> 58.43 | K2: =Tabela5[[#This Row],[Qtde Recebida]]/Tabela5[[#This Row],[Qtde Pedida]] -> 0.269625 | L2: 537.36 | M2: =IF(OR(J2="",L2=""),"",J2*L2) -> 31397.945 | N2: 46046 | O2: Parcial
A3: PC-2025-0013 | B3: 46012 | C3: AgroVale Distribuidora | D3: CAN-INO-002 | E3: =IFERROR(VLOOKUP(D3,Itens!$A$2:$E$51,2,FALSE),"") -> Bacillus spp. promotor de crescimento | F3: =IFERROR(VLOOKUP(D3,Itens!$A$2:$E$51,4,FALSE),"") -> Inoculante | G3: =IFERROR(VLOOKUP(D3,Itens!$A$2:$E$51,3,FALSE),"") -> kg | H3: 20 | I3: 0 | J3: =IF(H3="","",MAX(0,H3-IF(I3="",0,I3))) -> 20 | K3: =Tabela5[[#This Row],[Qtde Recebida]]/Tabela5[[#This Row],[Qtde Pedida]] -> 0 | L3: 119.82 | M3: =IF(OR(J3="",L3=""),"",J3*L3) -> 2396.4 | N3: 46073 | O3: Aberto
A4: PC-2025-0003 | B4: 46016 | C4: CoopCana | D4: CAN-HER-009 | E4: =IFERROR(VLOOKUP(D4,Itens!$A$2:$E$51,2,FALSE),"") -> Metolacloro 960 EC | F4: =IFERROR(VLOOKUP(D4,Itens!$A$2:$E$51,4,FALSE),"") -> Herbicida | G4: =IFERROR(VLOOKUP(D4,Itens!$A$2:$E$51,3,FALSE),"") -> L | H4: 100 | I4: 0 | J4: =IF(H4="","",MAX(0,H4-IF(I4="",0,I4))) -> 100 | K4: =Tabela5[[#This Row],[Qtde Recebida]]/Tabela5[[#This Row],[Qtde Pedida]] -> 0 | L4: 60.4 | M4: =IF(OR(J4="",L4=""),"",J4*L4) -> 6040 | N4: 46061 | O4: Aberto
A5: PC-2025-0009 | B5: 46022 | C5: Nutriplan | D5: CAN-FER-012 | E5: =IFERROR(VLOOKUP(D5,Itens!$A$2:$E$51,2,FALSE),"") -> NPK 08-28-16 | F5: =IFERROR(VLOOKUP(D5,Itens!$A$2:$E$51,4,FALSE),"") -> Fertilizante (NPK) | G5: =IFERROR(VLOOKUP(D5,Itens!$A$2:$E$51,3,FALSE),"") -> kg | H5: 2000 | I5: 0 | J5: =IF(H5="","",MAX(0,H5-IF(I5="",0,I5))) -> 2000 | K5: =Tabela5[[#This Row],[Qtde Recebida]]/Tabela5[[#This Row],[Qtde Pedida]] -> 0 | L5: 4.09 | M5: =IF(OR(J5="",L5=""),"",J5*L5) -> 8180 | N5: 46067 | O5: Aberto
A6: PC-2026-0010 | B6: 46023 | C6: CoopCana | D6: CAN-CAL-002 | E6: =IFERROR(VLOOKUP(D6,Itens!$A$2:$E$51,2,FALSE),"") -> Calcário calcítico (PRNT alto) | F6: =IFERROR(VLOOKUP(D6,Itens!$A$2:$E$51,4,FALSE),"") -> Corretivo (Calcário) | G6: =IFERROR(VLOOKUP(D6,Itens!$A$2:$E$51,3,FALSE),"") -> t | H6: 100 | I6: 46 | J6: =IF(H6="","",MAX(0,H6-IF(I6="",0,I6))) -> 54 | K6: =Tabela5[[#This Row],[Qtde Recebida]]/Tabela5[[#This Row],[Qtde Pedida]] -> 0.46 | L6: 172.82 | M6: =IF(OR(J6="",L6=""),"",J6*L6) -> 9332.28 | N6: 46062 | O6: Parcial
A7: PC-2026-0011 | B7: 46024 | C7: Nutriplan | D7: CAN-MIC-005 | E7: =IFERROR(VLOOKUP(D7,Itens!$A$2:$E$51,2,FALSE),"") -> Mistura de micronutrientes (B+Zn+Mn+Cu) | F7: =IFERROR(VLOOKUP(D7,Itens!$A$2:$E$51,4,FALSE),"") -> Micronutriente | G7: =IFERROR(VLOOKUP(D7,Itens!$A$2:$E$51,3,FALSE),"") -> kg | H7: 50 | I7: 25.23 | J7: =IF(H7="","",MAX(0,H7-IF(I7="",0,I7))) -> 24.77 | K7: =Tabela5[[#This Row],[Qtde Recebida]]/Tabela5[[#This Row],[Qtde Pedida]] -> 0.5046 | L7: 19.35 | M7: =IF(OR(J7="",L7=""),"",J7*L7) -> 479.2995 | N7: 46079 | O7: Parcial
A8: PC-2026-0007 | B8: 46026 | C8: Nutriplan | D8: CAN-FER-010 | E8: =IFERROR(VLOOKUP(D8,Itens!$A$2:$E$51,2,FALSE),"") -> NPK 20-00-20 | F8: =IFERROR(VLOOKUP(D8,Itens!$A$2:$E$51,4,FALSE),"") -> Fertilizante (NPK) | G8: =IFERROR(VLOOKUP(D8,Itens!$A$2:$E$51,3,FALSE),"") -> kg | H8: 5000 | I8: 1170 | J8: =IF(H8="","",MAX(0,H8-IF(I8="",0,I8))) -> 3830 | K8: =Tabela5[[#This Row],[Qtde Recebida]]/Tabela5[[#This Row],[Qtde Pedida]] -> 0.234 | L8: 3.41 | M8: =IF(OR(J8="",L8=""),"",J8*L8) -> 13060.3 | N8: 46059 | O8: Parcial
A9: PC-2026-0005 | B9: 46030 | C9: FertiMinas | D9: CAN-FER-009 | E9: =IFERROR(VLOOKUP(D9,Itens!$A$2:$E$51,2,FALSE),"") -> Superfosfato triplo (TSP) | F9: =IFERROR(VLOOKUP(D9,Itens!$A$2:$E$51,4,FALSE),"") -> Fosfatado | G9: =IFERROR(VLOOKUP(D9,Itens!$A$2:$E$51,3,FALSE),"") -> kg | H9: 8000 | I9: 810 | J9: =IF(H9="","",MAX(0,H9-IF(I9="",0,I9))) -> 7190 | K9: =Tabela5[[#This Row],[Qtde Recebida]]/Tabela5[[#This Row],[Qtde Pedida]] -> 0.10125 | L9: 3.2 | M9: =IF(OR(J9="",L9=""),"",J9*L9) -> 23008 | N9: 46080 | O9: Parcial
A10: PC-2026-0008 | B10: 46031 | C10: AgroVale Distribuidora | D10: CAN-HER-006 | E10: =IFERROR(VLOOKUP(D10,Itens!$A$2:$E$51,2,FALSE),"") -> Tebutiuron 500 WG | F10: =IFERROR(VLOOKUP(D10,Itens!$A$2:$E$51,4,FALSE),"") -> Herbicida | G10: =IFERROR(VLOOKUP(D10,Itens!$A$2:$E$51,3,FALSE),"") -> kg | H10: 5 | I10: 1.42 | J10: =IF(H10="","",MAX(0,H10-IF(I10="",0,I10))) -> 3.58 | K10: =Tabela5[[#This Row],[Qtde Recebida]]/Tabela5[[#This Row],[Qtde Pedida]] -> 0.284 | L10: 79.11 | M10: =IF(OR(J10="",L10=""),"",J10*L10) -> 283.2138 | N10: 46078 | O10: Parcial
A11: PC-2026-0002 | B11: 46033 | C11: Planta Forte Agro | D11: CAN-HER-003 | E11: =IFERROR(VLOOKUP(D11,Itens!$A$2:$E$51,2,FALSE),"") -> Atrazina 500 SC | F11: =IFERROR(VLOOKUP(D11,Itens!$A$2:$E$51,4,FALSE),"") -> Herbicida | G11: =IFERROR(VLOOKUP(D11,Itens!$A$2:$E$51,3,FALSE),"") -> L | H11: 150 | I11: 0 | J11: =IF(H11="","",MAX(0,H11-IF(I11="",0,I11))) -> 150 | K11: =Tabela5[[#This Row],[Qtde Recebida]]/Tabela5[[#This Row],[Qtde Pedida]] -> 0 | L11: 24.75 | M11: =IF(OR(J11="",L11=""),"",J11*L11) -> 3712.5 | N11: 46075 | O11: Aberto
A12: PC-2026-0014 | B12: 46035 | C12: Nutriplan | D12: CAN-FER-004 | E12: =IFERROR(VLOOKUP(D12,Itens!$A$2:$E$51,2,FALSE),"") -> Cloreto de potássio (KCl) 60% K2O | F12: =IFERROR(VLOOKUP(D12,Itens!$A$2:$E$51,4,FALSE),"") -> Fertilizante (K) | G12: =IFERROR(VLOOKUP(D12,Itens!$A$2:$E$51,3,FALSE),"") -> kg | H12: 5000 | I12: 2510 | J12: =IF(H12="","",MAX(0,H12-IF(I12="",0,I12))) -> 2490 | K12: =Tabela5[[#This Row],[Qtde Recebida]]/Tabela5[[#This Row],[Qtde Pedida]] -> 0.502 | L12: 3.22 | M12: =IF(OR(J12="",L12=""),"",J12*L12) -> 8017.8 | N12: 46063 | O12: Parcial
A13: PC-2026-0001 | B13: 46036 | C13: Nutriplan | D13: CAN-MIC-004 | E13: =IFERROR(VLOOKUP(D13,Itens!$A$2:$E$51,2,FALSE),"") -> Cobre (Cu) | F13: =IFERROR(VLOOKUP(D13,Itens!$A$2:$E$51,4,FALSE),"") -> Micronutriente | G13: =IFERROR(VLOOKUP(D13,Itens!$A$2:$E$51,3,FALSE),"") -> kg | H13: 80 | I13: 35.02 | J13: =IF(H13="","",MAX(0,H13-IF(I13="",0,I13))) -> 44.98 | K13: =Tabela5[[#This Row],[Qtde Recebida]]/Tabela5[[#This Row],[Qtde Pedida]] -> 0.43775 | L13: 24.37 | M13: =IF(OR(J13="",L13=""),"",J13*L13) -> 1096.1626 | N13: 46057 | O13: Parcial
... A15: PC-2026-0012 | B15: 46039 | C15: CoopCana | D15: CAN-FER-002 | E15: =IFERROR(VLOOKUP(D15,Itens!$A$2:$E$51,2,FALSE),"") -> Sulfato de amônio 21% N + 24% S | F15: =IFERROR(VLOOKUP(D15,Itens!$A$2:$E$51,4,FALSE),"") -> Fertilizante (N/S) | G15: =IFERROR(VLOOKUP(D15,Itens!$A$2:$E$51,3,FALSE),"") -> kg | H15: 8000 | I15: 4430 | J15: =IF(H15="","",MAX(0,H15-IF(I15="",0,I15))) -> 3570 | K15: =Tabela5[[#This Row],[Qtde Recebida]]/Tabela5[[#This Row],[Qtde Pedida]] -> 0.55375 | L15: 1.81 | M15: =IF(OR(J15="",L15=""),"",J15*L15) -> 6461.7 | N15: 46083 | O15: Parcial
E16: =IFERROR(VLOOKUP(D16,Itens!$A$2:$E$51,2,FALSE),"") | F16: =IFERROR(VLOOKUP(D16,Itens!$A$2:$E$51,4,FALSE),"") | G16: =IFERROR(VLOOKUP(D16,Itens!$A$2:$E$51,3,FALSE),"") | J16: =IF(H16="","",MAX(0,H16-IF(I16="",0,I16))) | M16: =IF(OR(J16="",L16=""),"",J16*L16)
E17: =IFERROR(VLOOKUP(D17,Itens!$A$2:$E$51,2,FALSE),"") | F17: =IFERROR(VLOOKUP(D17,Itens!$A$2:$E$51,4,FALSE),"") | G17: =IFERROR(VLOOKUP(D17,Itens!$A$2:$E$51,3,FALSE),"") | J17: =IF(H17="","",MAX(0,H17-IF(I17="",0,I17))) | M17: =IF(OR(J17="",L17=""),"",J17*L17)
E18: =IFERROR(VLOOKUP(D18,Itens!$A$2:$E$51,2,FALSE),"") | F18: =IFERROR(VLOOKUP(D18,Itens!$A$2:$E$51,4,FALSE),"") | G18: =IFERROR(VLOOKUP(D18,Itens!$A$2:$E$51,3,FALSE),"") | J18: =IF(H18="","",MAX(0,H18-IF(I18="",0,I18))) | M18: =IF(OR(J18="",L18=""),"",J18*L18)
E19: =IFERROR(VLOOKUP(D19,Itens!$A$2:$E$51,2,FALSE),"") | F19: =IFERROR(VLOOKUP(D19,Itens!$A$2:$E$51,4,FALSE),"") | G19: =IFERROR(VLOOKUP(D19,Itens!$A$2:$E$51,3,FALSE),"") | J19: =IF(H19="","",MAX(0,H19-IF(I19="",0,I19))) | M19: =IF(OR(J19="",L19=""),"",J19*L19)
E20: =IFERROR(VLOOKUP(D20,Itens!$A$2:$E$51,2,FALSE),"") | F20: =IFERROR(VLOOKUP(D20,Itens!$A$2:$E$51,4,FALSE),"") | G20: =IFERROR(VLOOKUP(D20,Itens!$A$2:$E$51,3,FALSE),"") | J20: =IF(H20="","",MAX(0,H20-IF(I20="",0,I20))) | M20: =IF(OR(J20="",L20=""),"",J20*L20)
E21: =IFERROR(VLOOKUP(D21,Itens!$A$2:$E$51,2,FALSE),"") | F21: =IFERROR(VLOOKUP(D21,Itens!$A$2:$E$51,4,FALSE),"") | G21: =IFERROR(VLOOKUP(D21,Itens!$A$2:$E$51,3,FALSE),"") | J21: =IF(H21="","",MAX(0,H21-IF(I21="",0,I21))) | M21: =IF(OR(J21="",L21=""),"",J21*L21)
E22: =IFERROR(VLOOKUP(D22,Itens!$A$2:$E$51,2,FALSE),"") | F22: =IFERROR(VLOOKUP(D22,Itens!$A$2:$E$51,4,FALSE),"") | G22: =IFERROR(VLOOKUP(D22,Itens!$A$2:$E$51,3,FALSE),"") | J22: =IF(H22="","",MAX(0,H22-IF(I22="",0,I22))) | M22: =IF(OR(J22="",L22=""),"",J22*L22)
E23: =IFERROR(VLOOKUP(D23,Itens!$A$2:$E$51,2,FALSE),"") | F23: =IFERROR(VLOOKUP(D23,Itens!$A$2:$E$51,4,FALSE),"") | G23: =IFERROR(VLOOKUP(D23,Itens!$A$2:$E$51,3,FALSE),"") | J23: =IF(H23="","",MAX(0,H23-IF(I23="",0,I23))) | M23: =IF(OR(J23="",L23=""),"",J23*L23)
E24: =IFERROR(VLOOKUP(D24,Itens!$A$2:$E$51,2,FALSE),"") | F24: =IFERROR(VLOOKUP(D24,Itens!$A$2:$E$51,4,FALSE),"") | G24: =IFERROR(VLOOKUP(D24,Itens!$A$2:$E$51,3,FALSE),"") | J24: =IF(H24="","",MAX(0,H24-IF(I24="",0,I24))) | M24: =IF(OR(J24="",L24=""),"",J24*L24)
E25: =IFERROR(VLOOKUP(D25,Itens!$A$2:$E$51,2,FALSE),"") | F25: =IFERROR(VLOOKUP(D25,Itens!$A$2:$E$51,4,FALSE),"") | G25: =IFERROR(VLOOKUP(D25,Itens!$A$2:$E$51,3,FALSE),"") | J25: =IF(H25="","",MAX(0,H25-IF(I25="",0,I25))) | M25: =IF(OR(J25="",L25=""),"",J25*L25)
E26: =IFERROR(VLOOKUP(D26,Itens!$A$2:$E$51,2,FALSE),"") | F26: =IFERROR(VLOOKUP(D26,Itens!$A$2:$E$51,4,FALSE),"") | G26: =IFERROR(VLOOKUP(D26,Itens!$A$2:$E$51,3,FALSE),"") | J26: =IF(H26="","",MAX(0,H26-IF(I26="",0,I26))) | M26: =IF(OR(J26="",L26=""),"",J26*L26)
E27: =IFERROR(VLOOKUP(D27,Itens!$A$2:$E$51,2,FALSE),"") | F27: =IFERROR(VLOOKUP(D27,Itens!$A$2:$E$51,4,FALSE),"") | G27: =IFERROR(VLOOKUP(D27,Itens!$A$2:$E$51,3,FALSE),"") | J27: =IF(H27="","",MAX(0,H27-IF(I27="",0,I27))) | M27: =IF(OR(J27="",L27=""),"",J27*L27)
... E121: =IFERROR(VLOOKUP(D121,Itens!$A$2:$E$51,2,FALSE),"") | F121: =IFERROR(VLOOKUP(D121,Itens!$A$2:$E$51,4,FALSE),"") | G121: =IFERROR(VLOOKUP(D121,Itens!$A$2:$E$51,3,FALSE),"") | J121: =IF(H121="","",MAX(0,H121-IF(I121="",0,I121))) | M121: =IF(OR(J121="",L121=""),"",J121*L121)

Sheet Estoque
A1: COD_ID | B1: Descrição | C1: Familia | D1: Localização | E1: Unidade | F1: Preço Médio (R$) | G1: Entradas | H1: Saídas | I1: Estoque Atual | J1: Saldo (%) | K1: Valor em Estoque (R$) | L1: Em pedido (aberto) | M1: Estoque + Pedido | N1: Valor Potencial (R$)
A2: CAN-HER-001 | B2: =VLOOKUP(Tabela4[[#This Row],[COD_ID]],Itens!A:B,2,0) -> Glifosato 480 SL | C2: Herbicida | D2: Controle de Químicos | E2: L | F2: =IFERROR(VLOOKUP(A2,Itens!$A$2:$E$51,5,FALSE),0) -> 22 | G2: =SUMIFS(Entradas!$H$2:$H$48,Entradas!$D$2:$D$48,A2) -> 150 | H2: =SUMIFS(Saidas!$H$2:$H$71,Saidas!$D$2:$D$71,A2) -> 102.59 | I2: =G2-H2 -> 47.41 | J2: =IFERROR(Tabela4[[#This Row],[Estoque Atual]]/Tabela4[[#This Row],[Entradas]],0) -> 0.31606667 | K2: =I2*F2 -> 1043.02 | L2: =SUMIFS(Pedidos_Compra!$J$2:$J$121,Pedidos_Compra!$D$2:$D$121,A2) -> 0 | M2: =I2+L2 -> 47.41 | N2: =M2*F2 -> 1043.02
A3: CAN-HER-002 | B3: =VLOOKUP(Tabela4[[#This Row],[COD_ID]],Itens!A:B,2,0) -> 2,4-D (sal amina) | C3: Herbicida | D3: Controle de Químicos | E3: L | F3: =IFERROR(VLOOKUP(A3,Itens!$A$2:$E$51,5,FALSE),0) -> 18 | G3: =SUMIFS(Entradas!$H$2:$H$48,Entradas!$D$2:$D$48,A3) -> 250 | H3: =SUMIFS(Saidas!$H$2:$H$71,Saidas!$D$2:$D$71,A3) -> 166.78 | I3: =G3-H3 -> 83.22 | J3: =IFERROR(Tabela4[[#This Row],[Estoque Atual]]/Tabela4[[#This Row],[Entradas]],0) -> 0.33288 | K3: =I3*F3 -> 1497.96 | L3: =SUMIFS(Pedidos_Compra!$J$2:$J$121,Pedidos_Compra!$D$2:$D$121,A3) -> 80 | M3: =I3+L3 -> 163.22 | N3: =M3*F3 -> 2937.96
A4: CAN-HER-003 | B4: =VLOOKUP(Tabela4[[#This Row],[COD_ID]],Itens!A:B,2,0) -> Atrazina 500 SC | C4: Herbicida | D4: Controle de Químicos | E4: L | F4: =IFERROR(VLOOKUP(A4,Itens!$A$2:$E$51,5,FALSE),0) -> 24 | G4: =SUMIFS(Entradas!$H$2:$H$48,Entradas!$D$2:$D$48,A4) -> 50 | H4: =SUMIFS(Saidas!$H$2:$H$71,Saidas!$D$2:$D$71,A4) -> 20.77 | I4: =G4-H4 -> 29.23 | J4: =IFERROR(Tabela4[[#This Row],[Estoque Atual]]/Tabela4[[#This Row],[Entradas]],0) -> 0.5846 | K4: =I4*F4 -> 701.52 | L4: =SUMIFS(Pedidos_Compra!$J$2:$J$121,Pedidos_Compra!$D$2:$D$121,A4) -> 150 | M4: =I4+L4 -> 179.23 | N4: =M4*F4 -> 4301.52
A5: CAN-HER-004 | B5: =VLOOKUP(Tabela4[[#This Row],[COD_ID]],Itens!A:B,2,0) -> Hexazinona 250 SC | C5: Herbicida | D5: Controle de Químicos | E5: L | F5: =IFERROR(VLOOKUP(A5,Itens!$A$2:$E$51,5,FALSE),0) -> 110 | G5: =SUMIFS(Entradas!$H$2:$H$48,Entradas!$D$2:$D$48,A5) -> 120 | H5: =SUMIFS(Saidas!$H$2:$H$71,Saidas!$D$2:$D$71,A5) -> 92.08 | I5: =G5-H5 -> 27.92 | J5: =IFERROR(Tabela4[[#This Row],[Estoque Atual]]/Tabela4[[#This Row],[Entradas]],0) -> 0.23266667 | K5: =I5*F5 -> 3071.2 | L5: =SUMIFS(Pedidos_Compra!$J$2:$J$121,Pedidos_Compra!$D$2:$D$121,A5) -> 0 | M5: =I5+L5 -> 27.92 | N5: =M5*F5 -> 3071.2
A6: CAN-HER-005 | B6: =VLOOKUP(Tabela4[[#This Row],[COD_ID]],Itens!A:B,2,0) -> Diuron 500 SC | C6: Herbicida | D6: Controle de Químicos | E6: L | F6: =IFERROR(VLOOKUP(A6,Itens!$A$2:$E$51,5,FALSE),0) -> 30 | G6: =SUMIFS(Entradas!$H$2:$H$48,Entradas!$D$2:$D$48,A6) -> 250 | H6: =SUMIFS(Saidas!$H$2:$H$71,Saidas!$D$2:$D$71,A6) -> 181.18 | I6: =G6-H6 -> 68.82 | J6: =IFERROR(Tabela4[[#This Row],[Estoque Atual]]/Tabela4[[#This Row],[Entradas]],0) -> 0.27528 | K6: =I6*F6 -> 2064.6 | L6: =SUMIFS(Pedidos_Compra!$J$2:$J$121,Pedidos_Compra!$D$2:$D$121,A6) -> 0 | M6: =I6+L6 -> 68.82 | N6: =M6*F6 -> 2064.6
A7: CAN-HER-006 | B7: =VLOOKUP(Tabela4[[#This Row],[COD_ID]],Itens!A:B,2,0) -> Tebutiuron 500 WG | C7: Herbicida | D7: Deposito 1 | E7: kg | F7: =IFERROR(VLOOKUP(A7,Itens!$A$2:$E$51,5,FALSE),0) -> 75 | G7: =SUMIFS(Entradas!$H$2:$H$48,Entradas!$D$2:$D$48,A7) -> 10 | H7: =SUMIFS(Saidas!$H$2:$H$71,Saidas!$D$2:$D$71,A7) -> 0 | I7: =G7-H7 -> 10 | J7: =IFERROR(Tabela4[[#This Row],[Estoque Atual]]/Tabela4[[#This Row],[Entradas]],0) -> 1 | K7: =I7*F7 -> 750 | L7: =SUMIFS(Pedidos_Compra!$J$2:$J$121,Pedidos_Compra!$D$2:$D$121,A7) -> 3.58 | M7: =I7+L7 -> 13.58 | N7: =M7*F7 -> 1018.5
A8: CAN-HER-007 | B8: =VLOOKUP(Tabela4[[#This Row],[COD_ID]],Itens!A:B,2,0) -> Imazapic 700 WG | C8: Herbicida | D8: Deposito 1 | E8: kg | F8: =IFERROR(VLOOKUP(A8,Itens!$A$2:$E$51,5,FALSE),0) -> 320 | G8: =SUMIFS(Entradas!$H$2:$H$48,Entradas!$D$2:$D$48,A8) -> 50 | H8: =SUMIFS(Saidas!$H$2:$H$71,Saidas!$D$2:$D$71,A8) -> 37.06 | I8: =G8-H8 -> 12.94 | J8: =IFERROR(Tabela4[[#This Row],[Estoque Atual]]/Tabela4[[#This Row],[Entradas]],0) -> 0.2588 | K8: =I8*F8 -> 4140.8 | L8: =SUMIFS(Pedidos_Compra!$J$2:$J$121,Pedidos_Compra!$D$2:$D$121,A8) -> 0 | M8: =I8+L8 -> 12.94 | N8: =M8*F8 -> 4140.8
A9: CAN-HER-008 | B9: =VLOOKUP(Tabela4[[#This Row],[COD_ID]],Itens!A:B,2,0) -> Amicarbazona 700 WG | C9: Herbicida | D9: Deposito 1 | E9: kg | F9: =IFERROR(VLOOKUP(A9,Itens!$A$2:$E$51,5,FALSE),0) -> 280 | G9: =SUMIFS(Entradas!$H$2:$H$48,Entradas!$D$2:$D$48,A9) -> 0 | H9: =SUMIFS(Saidas!$H$2:$H$71,Saidas!$D$2:$D$71,A9) -> 0 | I9: =G9-H9 -> 0 | J9: =IFERROR(Tabela4[[#This Row],[Estoque Atual]]/Tabela4[[#This Row],[Entradas]],0) -> 0 | K9: =I9*F9 -> 0 | L9: =SUMIFS(Pedidos_Compra!$J$2:$J$121,Pedidos_Compra!$D$2:$D$121,A9) -> 0 | M9: =I9+L9 -> 0 | N9: =M9*F9 -> 0
A10: CAN-HER-009 | B10: =VLOOKUP(Tabela4[[#This Row],[COD_ID]],Itens!A:B,2,0) -> Metolacloro 960 EC | C10: Herbicida | D10: Controle de Químicos | E10: L | F10: =IFERROR(VLOOKUP(A10,Itens!$A$2:$E$51,5,FALSE),0) -> 55 | G10: =SUMIFS(Entradas!$H$2:$H$48,Entradas!$D$2:$D$48,A10) -> 120 | H10: =SUMIFS(Saidas!$H$2:$H$71,Saidas!$D$2:$D$71,A10) -> 0 | I10: =G10-H10 -> 120 | J10: =IFERROR(Tabela4[[#This Row],[Estoque Atual]]/Tabela4[[#This Row],[Entradas]],0) -> 1 | K10: =I10*F10 -> 6600 | L10: =SUMIFS(Pedidos_Compra!$J$2:$J$121,Pedidos_Compra!$D$2:$D$121,A10) -> 100 | M10: =I10+L10 -> 220 | N10: =M10*F10 -> 12100
A11: CAN-HER-010 | B11: =VLOOKUP(Tabela4[[#This Row],[COD_ID]],Itens!A:B,2,0) -> MSMA (concentrado solúvel) | C11: Herbicida | D11: Controle de Químicos | E11: L | F11: =IFERROR(VLOOKUP(A11,Itens!$A$2:$E$51,5,FALSE),0) -> 45 | G11: =SUMIFS(Entradas!$H$2:$H$48,Entradas!$D$2:$D$48,A11) -> 120 | H11: =SUMIFS(Saidas!$H$2:$H$71,Saidas!$D$2:$D$71,A11) -> 62.98 | I11: =G11-H11 -> 57.02 | J11: =IFERROR(Tabela4[[#This Row],[Estoque Atual]]/Tabela4[[#This Row],[Entradas]],0) -> 0.47516667 | K11: =I11*F11 -> 2565.9 | L11: =SUMIFS(Pedidos_Compra!$J$2:$J$121,Pedidos_Compra!$D$2:$D$121,A11) -> 0 | M11: =I11+L11 -> 57.02 | N11: =M11*F11 -> 2565.9
A12: CAN-INS-001 | B12: =VLOOKUP(Tabela4[[#This Row],[COD_ID]],Itens!A:B,2,0) -> Inseticida – Imidacloprido 200 SL | C12: Inseticida | D12: Controle de Químicos | E12: L | F12: =IFERROR(VLOOKUP(A12,Itens!$A$2:$E$51,5,FALSE),0) -> 120 | G12: =SUMIFS(Entradas!$H$2:$H$48,Entradas!$D$2:$D$48,A12) -> 200 | H12: =SUMIFS(Saidas!$H$2:$H$71,Saidas!$D$2:$D$71,A12) -> 97.86 | I12: =G12-H12 -> 102.14 | J12: =IFERROR(Tabela4[[#This Row],[Estoque Atual]]/Tabela4[[#This Row],[Entradas]],0) -> 0.5107 | K12: =I12*F12 -> 12256.8 | L12: =SUMIFS(Pedidos_Compra!$J$2:$J$121,Pedidos_Compra!$D$2:$D$121,A12) -> 0 | M12: =I12+L12 -> 102.14 | N12: =M12*F12 -> 12256.8
A13: CAN-INS-002 | B13: =VLOOKUP(Tabela4[[#This Row],[COD_ID]],Itens!A:B,2,0) -> Tiametoxam 250 WG | C13: Inseticida | D13: Deposito 1 | E13: kg | F13: =IFERROR(VLOOKUP(A13,Itens!$A$2:$E$51,5,FALSE),0) -> 400 | G13: =SUMIFS(Entradas!$H$2:$H$48,Entradas!$D$2:$D$48,A13) -> 15 | H13: =SUMIFS(Saidas!$H$2:$H$71,Saidas!$D$2:$D$71,A13) -> 12.61 | I13: =G13-H13 -> 2.39 | J13: =IFERROR(Tabela4[[#This Row],[Estoque Atual]]/Tabela4[[#This Row],[Entradas]],0) -> 0.15933333 | K13: =I13*F13 -> 956 | L13: =SUMIFS(Pedidos_Compra!$J$2:$J$121,Pedidos_Compra!$D$2:$D$121,A13) -> 0 | M13: =I13+L13 -> 2.39 | N13: =M13*F13 -> 956
... A51: CAN-ADJ-002 | B51: =VLOOKUP(Tabela4[[#This Row],[COD_ID]],Itens!A:B,2,0) -> Espalhante adesivo não iônico | C51: Adjuvante | D51: Controle de Químicos | E51: L | F51: =IFERROR(VLOOKUP(A51,Itens!$A$2:$E$51,5,FALSE),0) -> 35 | G51: =SUMIFS(Entradas!$H$2:$H$48,Entradas!$D$2:$D$48,A51) -> 150 | H51: =SUMIFS(Saidas!$H$2:$H$71,Saidas!$D$2:$D$71,A51) -> 127.25 | I51: =G51-H51 -> 22.75 | J51: =IFERROR(Tabela4[[#This Row],[Estoque Atual]]/Tabela4[[#This Row],[Entradas]],0) -> 0.15166667 | K51: =I51*F51 -> 796.25 | L51: =SUMIFS(Pedidos_Compra!$J$2:$J$121,Pedidos_Compra!$D$2:$D$121,A51) -> 0 | M51: =I51+L51 -> 22.75 | N51: =M51*F51 -> 796.25
